Workbook
Name A6948.: #REF!
Name A6948.: #REF!
Name B: #REF!
Name B: #REF!
Name FDFS: #REF!
Name FDFS: #REF!
Name Insert_Group_Detail: #REF!
Name Insert_Group_Detail: #REF!
Name NBHJG: #REF!
Name NBHJG: #REF!
Name ش4475: #REF!
Name ش4475: #REF!
Name ش542: #REF!
Name ش542: #REF!

Sheet FULT EMS
A1: تاریخ | B1: شیفت کاری | C1: کد گروه محصول | D1: کد محصول | E1: نام محصول | F1: خانواده محصول | G1: نام محصول ترکیبی | H1: گروه محصول نهایی | I1: ایستگاه | J1: کد ایراد | K1: شرح ایراد | L1: تعداد ایراد | M1: تعداد کل | N1: برنچ | O1: شرح فعالیت انجام شده توسط تعمیرات | P1: عامل مسبب ایراد 6M | Q1: کد قطعه | R1: نام قطعه | S1: نام تامین کننده | T1: کد و نام تجهیزات و ابزارآلات | U1: کد تجهیزات و ابزارآلات | V1: کد و نام تجهیزات و ابزارآلات1 | W1: کد فرآیند (OPC) | X1: نام فرآیند (OPC) | Y1: حالت خرابی بالقوه | Z1: نوع حالت خرابی بالقوه | AA1: توضیحات تعمیرات | AB1: ستون مشترک حالت خرابی | AC1: شدت حالت خرابی | AD1: تشخیص حالت خرابی | AE1: وقوع قدیمی | AF1: مدت زمان عیب یابی ( دقیقه ) | AG1: مدت زمان رفع عیب ( دقیقه ) | AH1: مدت زمان تست مجدد ( دقیقه ) | AI1: هزینه ریالی تعمیرات | AJ1: خانواده قطعات | AK1: شماره BOM | AL1: شماره برگ ارسال | AM1: کد اپراتور | AN1: نام اپراتور | AO1: کد بازرس چشمی | AP1: نام بازرس | AQ1: AOI | AR1: نام بازرس AOI | AS1: نوع قطعات تولیدی و تامینی | AT1: وضعیت اعلام ایرادات | AU1: توضیحات اضافه | AV1: توضیحات | AW1: Control Station | AX1: حد قابل قبول | AY1: هدف | AZ1: علت افت یا بهبود PPM | BA1: حد قابل قبول عظام | BB1: هدف عظام
A2: 1405/05/01 | B2: عادی | C2: 3201031 | D2: جعبه الکترونیکی ایموبلایزر EIM -تکمیل کاری شده | E2: =VLOOKUP(C2,Table1[],3,0) -> #N/A | F2: =VLOOKUP(C2,Table1[],4,0) -> #N/A | G2: =VLOOKUP(C2,Table1[],5,0) -> #N/A | H2: =VLOOKUP(C2,Table1[],6,0) -> #N/A | I2: مونتاژ انتن و یونیت ایمو بلایزر | J2: FTD-862 | K2: عملکردی | L2: 3 | M2: 0 | N2: EMS | O2: - | P2: - | Q2: - | R2: - | S2: - | T2: - | U2: - | V2: - | W2: - | X2: - | Y2: - | Z2: - | AA2: - | AB2: - | AC2: 0 | AD2: 0 | AE2: 0 | AF2: 0 | AG2: 0 | AH2: 0 | AI2: 44000 | AJ2: - | AK2: - | AL2: - | AM2: - | AN2: - | AO2: - | AP2: - | AQ2: - | AR2: - | AS2: فرآیندی | AT2: - | AU2: - | AV2: - | AW2: - | AX2: 14000 | AY2: 12000 | AZ2: - | BA2: 14000 | BB2: 12000
A3: 1405/05/01 | B3: عادی | C3: 3204301 | D3: آنتن ایموبلایزر ssat | E3: =VLOOKUP(C3,Table1[],3,0) -> آنتن ايموبلايزر XU7 - S -XUP مونتاژی | F3: =VLOOKUP(C3,Table1[],4,0) -> آنتن ايموبلايزر | G3: =VLOOKUP(C3,Table1[],5,0) -> آنتن ايموبلايزر XU7 - S -XUP مونتاژی | H3: =VLOOKUP(C3,Table1[],6,0) -> EMS-توسعه و نگاشت موتور | I3: مونتاژ انتن و یونیت ایمو بلایزر | J3: AD-880 | K3: ایراد مونتاژی سیم در قرقره | L3: 1 | M3: 0 | N3: EMS | O3: - | P3: - | Q3: - | R3: - | S3: - | T3: - | U3: - | V3: - | W3: - | X3: - | Y3: - | Z3: - | AA3: - | AB3: - | AC3: 0 | AD3: 0 | AE3: 0 | AF3: 0 | AG3: 0 | AH3: 0 | AI3: 44000 | AJ3: - | AK3: - | AL3: - | AM3: - | AN3: - | AO3: - | AP3: - | AQ3: - | AR3: - | AS3: فرآیندی | AT3: - | AU3: - | AV3: - | AW3: - | AX3: 14000 | AY3: 12000 | AZ3: - | BA3: 14000 | BB3: 12000
A4: 1405/05/01 | B4: عادی | C4: 3204200 | D4: پدال گاز برقی ME17 TU5-بازویی بلند | E4: =VLOOKUP(C4,Table1[],3,0) -> #N/A | F4: =VLOOKUP(C4,Table1[],4,0) -> #N/A | G4: =VLOOKUP(C4,Table1[],5,0) -> #N/A | H4: =VLOOKUP(C4,Table1[],6,0) -> #N/A | I4: مونتاژ پدال گاز برقی | J4: AD-816 | K4: رد شدن فیلر0.02 | L4: 2 | M4: 0 | N4: EMS | O4: - | P4: - | Q4: - | R4: - | S4: - | T4: - | U4: - | V4: - | W4: - | X4: - | Y4: - | Z4: - | AA4: - | AB4: - | AC4: 0 | AD4: 0 | AE4: 0 | AF4: 0 | AG4: 0 | AH4: 0 | AI4: 44000 | AJ4: - | AK4: - | AL4: - | AM4: - | AN4: - | AO4: - | AP4: - | AQ4: - | AR4: - | AS4: فرآیندی | AT4: - | AU4: - | AV4: - | AW4: - | AX4: 14000 | AY4: 12000 | AZ4: - | BA4: 14000 | BB4: 12000
A5: 1405/05/01 | B5: عادی | C5: 3204200 | D5: پدال گاز برقی ME17 TU5-بازویی بلند | E5: =VLOOKUP(C5,Table1[],3,0) -> #N/A | F5: =VLOOKUP(C5,Table1[],4,0) -> #N/A | G5: =VLOOKUP(C5,Table1[],5,0) -> #N/A | H5: =VLOOKUP(C5,Table1[],6,0) -> #N/A | I5: مونتاژ پدال گاز برقی | J5: AD-828 | K5: عدم مونتاژ مناسب پیچ | L5: 6 | M5: 0 | N5: EMS | O5: - | P5: - | Q5: - | R5: - | S5: - | T5: - | U5: - | V5: - | W5: - | X5: - | Y5: - | Z5: - | AA5: - | AB5: - | AC5: 0 | AD5: 0 | AE5: 0 | AF5: 0 | AG5: 0 | AH5: 0 | AI5: 44000 | AJ5: - | AK5: - | AL5: - | AM5: - | AN5: - | AO5: - | AP5: - | AQ5: - | AR5: - | AS5: فرآیندی | AT5: - | AU5: - | AV5: - | AW5: - | AX5: 14000 | AY5: 12000 | AZ5: - | BA5: 14000 | BB5: 12000
A6: 1405/05/01 | B6: عادی | C6: 3204200 | D6: پدال گاز برقی ME17 TU5-بازویی بلند | E6: =VLOOKUP(C6,Table1[],3,0) -> #N/A | F6: =VLOOKUP(C6,Table1[],4,0) -> #N/A | G6: =VLOOKUP(C6,Table1[],5,0) -> #N/A | H6: =VLOOKUP(C6,Table1[],6,0) -> #N/A | I6: مونتاژ پدال گاز برقی | J6: FTD-832 | K6: ایراد تطابق(SYNCHRONIEITY) | L6: 3 | M6: 0 | N6: EMS | O6: - | P6: - | Q6: - | R6: - | S6: - | T6: - | U6: - | V6: - | W6: - | X6: - | Y6: - | Z6: - | AA6: - | AB6: - | AC6: 0 | AD6: 0 | AE6: 0 | AF6: 0 | AG6: 0 | AH6: 0 | AI6: 44000 | AJ6: - | AK6: - | AL6: - | AM6: - | AN6: - | AO6: - | AP6: - | AQ6: - | AR6: - | AS6: فرآیندی | AT6: - | AU6: - | AV6: - | AW6: - | AX6: 14000 | AY6: 12000 | AZ6: - | BA6: 14000 | BB6: 12000
A7: 1405/05/03 | B7: عادی | C7: 3201031 | D7: جعبه الکترونیکی ایموبلایزر EIM -تکمیل کاری شده | E7: =VLOOKUP(C7,Table1[],3,0) -> #N/A | F7: =VLOOKUP(C7,Table1[],4,0) -> #N/A | G7: =VLOOKUP(C7,Table1[],5,0) -> #N/A | H7: =VLOOKUP(C7,Table1[],6,0) -> #N/A | I7: مونتاژ انتن و یونیت ایمو بلایزر | J7: FTD-862 | K7: عملکردی | L7: 3 | M7: 0 | N7: EMS | O7: - | P7: - | Q7: - | R7: - | S7: - | T7: - | U7: - | V7: - | W7: - | X7: - | Y7: - | Z7: - | AA7: - | AB7: - | AC7: 0 | AD7: 0 | AE7: 0 | AF7: 0 | AG7: 0 | AH7: 0 | AI7: 44000 | AJ7: - | AK7: - | AL7: - | AM7: - | AN7: - | AO7: - | AP7: - | AQ7: - | AR7: - | AS7: فرآیندی | AT7: - | AU7: - | AV7: - | AW7: - | AX7: 14000 | AY7: 12000 | AZ7: - | BA7: 14000 | BB7: 12000
A8: 1405/05/03 | B8: عادی | C8: 3204101 | D8: پدال گاز برقی XUP | E8: =VLOOKUP(C8,Table1[],3,0) -> #N/A | F8: =VLOOKUP(C8,Table1[],4,0) -> #N/A | G8: =VLOOKUP(C8,Table1[],5,0) -> #N/A | H8: =VLOOKUP(C8,Table1[],6,0) -> #N/A | I8: مونتاژ پدال گاز برقی | J8: AD-816 | K8: رد شدن فیلر0.02 | L8: 1 | M8: 0 | N8: EMS | O8: - | P8: - | Q8: - | R8: - | S8: - | T8: - | U8: - | V8: - | W8: - | X8: - | Y8: - | Z8: - | AA8: - | AB8: - | AC8: 0 | AD8: 0 | AE8: 0 | AF8: 0 | AG8: 0 | AH8: 0 | AI8: 44000 | AJ8: - | AK8: - | AL8: - | AM8: - | AN8: - | AO8: - | AP8: - | AQ8: - | AR8: - | AS8: فرآیندی | AT8: - | AU8: - | AV8: - | AW8: - | AX8: 14000 | AY8: 12000 | AZ8: - | BA8: 14000 | BB8: 12000
A9: 1405/05/03 | B9: عادی | C9: 3204101 | D9: پدال گاز برقی XUP | E9: =VLOOKUP(C9,Table1[],3,0) -> #N/A | F9: =VLOOKUP(C9,Table1[],4,0) -> #N/A | G9: =VLOOKUP(C9,Table1[],5,0) -> #N/A | H9: =VLOOKUP(C9,Table1[],6,0) -> #N/A | I9: مونتاژ پدال گاز برقی | J9: AD-828 | K9: عدم مونتاژ مناسب پیچ | L9: 2 | M9: 0 | N9: EMS | O9: - | P9: - | Q9: - | R9: - | S9: - | T9: - | U9: - | V9: - | W9: - | X9: - | Y9: - | Z9: - | AA9: - | AB9: - | AC9: 0 | AD9: 0 | AE9: 0 | AF9: 0 | AG9: 0 | AH9: 0 | AI9: 44000 | AJ9: - | AK9: - | AL9: - | AM9: - | AN9: - | AO9: - | AP9: - | AQ9: - | AR9: - | AS9: فرآیندی | AT9: - | AU9: - | AV9: - | AW9: - | AX9: 14000 | AY9: 12000 | AZ9: - | BA9: 14000 | BB9: 12000
A10: 1405/05/03 | B10: عادی | C10: 3204101 | D10: پدال گاز برقی XUP | E10: =VLOOKUP(C10,Table1[],3,0) -> #N/A | F10: =VLOOKUP(C10,Table1[],4,0) -> #N/A | G10: =VLOOKUP(C10,Table1[],5,0) -> #N/A | H10: =VLOOKUP(C10,Table1[],6,0) -> #N/A | I10: مونتاژ پدال گاز برقی | J10: FTD-824 | K10: ISOLATION | L10: 1 | M10: 0 | N10: EMS | O10: - | P10: - | Q10: - | R10: - | S10: - | T10: - | U10: - | V10: - | W10: - | X10: - | Y10: - | Z10: - | AA10: - | AB10: - | AC10: 0 | AD10: 0 | AE10: 0 | AF10: 0 | AG10: 0 | AH10: 0 | AI10: 44000 | AJ10: - | AK10: - | AL10: - | AM10: - | AN10: - | AO10: - | AP10: - | AQ10: - | AR10: - | AS10: فرآیندی | AT10: - | AU10: - | AV10: - | AW10: - | AX10: 14000 | AY10: 12000 | AZ10: - | BA10: 14000 | BB10: 12000
A11: 1405/05/04 | B11: عادی | C11: 3201031 | D11: جعبه الکترونیکی ایموبلایزر EIM -تکمیل کاری شده | E11: =VLOOKUP(C11,Table1[],3,0) -> #N/A | F11: =VLOOKUP(C11,Table1[],4,0) -> #N/A | G11: =VLOOKUP(C11,Table1[],5,0) -> #N/A | H11: =VLOOKUP(C11,Table1[],6,0) -> #N/A | I11: مونتاژ انتن و یونیت ایمو بلایزر | J11: FTD-865 | K11: فلش نمیشود | L11: 1 | M11: 0 | N11: EMS | O11: - | P11: - | Q11: - | R11: - | S11: - | T11: - | U11: - | V11: - | W11: - | X11: - | Y11: - | Z11: - | AA11: - | AB11: - | AC11: 0 | AD11: 0 | AE11: 0 | AF11: 0 | AG11: 0 | AH11: 0 | AI11: 44000 | AJ11: - | AK11: - | AL11: - | AM11: - | AN11: - | AO11: - | AP11: - | AQ11: - | AR11: - | AS11: فرآیندی | AT11: - | AU11: - | AV11: - | AW11: - | AX11: 14000 | AY11: 12000 | AZ11: - | BA11: 14000 | BB11: 12000
A12: 1405/05/04 | B12: عادی | C12: 3201031 | D12: جعبه الکترونیکی ایموبلایزر EIM -تکمیل کاری شده | E12: =VLOOKUP(C12,Table1[],3,0) -> #N/A | F12: =VLOOKUP(C12,Table1[],4,0) -> #N/A | G12: =VLOOKUP(C12,Table1[],5,0) -> #N/A | H12: =VLOOKUP(C12,Table1[],6,0) -> #N/A | I12: مونتاژ انتن و یونیت ایمو بلایزر | J12: FTD-862 | K12: عملکردی | L12: 1 | M12: 0 | N12: EMS | O12: - | P12: - | Q12: - | R12: - | S12: - | T12: - | U12: - | V12: - | W12: - | X12: - | Y12: - | Z12: - | AA12: - | AB12: - | AC12: 0 | AD12: 0 | AE12: 0 | AF12: 0 | AG12: 0 | AH12: 0 | AI12: 44000 | AJ12: - | AK12: - | AL12: - | AM12: - | AN12: - | AO12: - | AP12: - | AQ12: - | AR12: - | AS12: فرآیندی | AT12: - | AU12: - | AV12: - | AW12: - | AX12: 14000 | AY12: 12000 | AZ12: - | BA12: 14000 | BB12: 12000
A13: 1405/05/04 | B13: عادی | C13: 3204101 | D13: پدال گاز برقی XUP | E13: =VLOOKUP(C13,Table1[],3,0) -> #N/A | F13: =VLOOKUP(C13,Table1[],4,0) -> #N/A | G13: =VLOOKUP(C13,Table1[],5,0) -> #N/A | H13: =VLOOKUP(C13,Table1[],6,0) -> #N/A | I13: مونتاژ پدال گاز برقی | J13: AD-815 | K13: شکل ظاهری | L13: 1 | M13: 0 | N13: EMS | O13: - | P13: - | Q13: - | R13: - | S13: - | T13: - | U13: - | V13: - | W13: - | X13: - | Y13: - | Z13: - | AA13: - | AB13: - | AC13: 0 | AD13: 0 | AE13: 0 | AF13: 0 | AG13: 0 | AH13: 0 | AI13: 44000 | AJ13: - | AK13: - | AL13: - | AM13: - | AN13: - | AO13: - | AP13: - | AQ13: - | AR13: - | AS13: فرآیندی | AT13: - | AU13: - | AV13: - | AW13: - | AX13: 14000 | AY13: 12000 | AZ13: - | BA13: 14000 | BB13: 12000
... A77: 1405/05/31 | B77: عادی | C77: 3204200 | D77: پدال گاز برقی ME17 TU5-بازویی بلند | E77: =VLOOKUP(C77,Table1[],3,0) -> #N/A | F77: =VLOOKUP(C77,Table1[],4,0) -> #N/A | G77: =VLOOKUP(C77,Table1[],5,0) -> #N/A | H77: =VLOOKUP(C77,Table1[],6,0) -> #N/A | I77: مونتاژ پدال گاز برقی | J77: FTD-824 | K77: ISOLATION | L77: 1 | M77: 0 | N77: EMS | O77: - | P77: - | Q77: - | R77: - | S77: - | T77: - | U77: - | V77: - | W77: - | X77: - | Y77: - | Z77: - | AA77: - | AB77: - | AC77: 0 | AD77: 0 | AE77: 0 | AF77: 0 | AG77: 0 | AH77: 0 | AI77: 44000 | AJ77: - | AK77: - | AL77: - | AM77: - | AN77: - | AO77: - | AP77: - | AQ77: - | AR77: - | AS77: فرآیندی | AT77: - | AU77: - | AV77: - | AW77: - | AX77: 14000 | AY77: 12000 | AZ77: - | BA77: 14000 | BB77: 12000
A78: 1405/05/01 | C78: 3206133 | D78: ECU S4 4coil Without Vent تکمیل کاری شده | E78: =VLOOKUP(C78,Table1[],3,0) -> ECU S4 4coil | F78: =VLOOKUP(C78,Table1[],4,0) -> ECU مونتاژی | G78: =VLOOKUP(C78,Table1[],5,0) -> ECU S4 4coil | H78: =VLOOKUP(C78,Table1[],6,0) -> EMS-توسعه و نگاشت موتور | I78: تکمیل کاری ECU | J78: - | K78: - | L78: 0 | M78: 660 | N78: EMS | O78: - | P78: - | Q78: - | R78: - | S78: - | T78: - | U78: - | V78: - | W78: - | X78: - | Y78: - | Z78: - | AA78: - | AB78: - | AC78: 0 | AD78: 0 | AE78: 0 | AF78: 0 | AG78: 0 | AH78: 0 | AI78: 44000 | AJ78: - | AK78: - | AL78: - | AM78: - | AN78: - | AO78: - | AP78: - | AQ78: - | AR78: - | AS78: فرآیندی | AT78: - | AU78: - | AV78: - | AW78: - | AX78: 14000 | AY78: 12000 | AZ78: - | BA78: 14000 | BB78: 12000
A79: 1405/05/03 | C79: 3206133 | D79: ECU S4 4coil Without Vent تکمیل کاری شده | E79: =VLOOKUP(C79,Table1[],3,0) -> ECU S4 4coil | F79: =VLOOKUP(C79,Table1[],4,0) -> ECU مونتاژی | G79: =VLOOKUP(C79,Table1[],5,0) -> ECU S4 4coil | H79: =VLOOKUP(C79,Table1[],6,0) -> EMS-توسعه و نگاشت موتور | I79: تکمیل کاری ECU | J79: - | K79: - | L79: 0 | M79: 730 | N79: EMS | O79: - | P79: - | Q79: - | R79: - | S79: - | T79: - | U79: - | V79: - | W79: - | X79: - | Y79: - | Z79: - | AA79: - | AB79: - | AC79: 0 | AD79: 0 | AE79: 0 | AF79: 0 | AG79: 0 | AH79: 0 | AI79: 44000 | AJ79: - | AK79: - | AL79: - | AM79: - | AN79: - | AO79: - | AP79: - | AQ79: - | AR79: - | AS79: فرآیندی | AT79: - | AU79: - | AV79: - | AW79: - | AX79: 14000 | AY79: 12000 | AZ79: - | BA79: 14000 | BB79: 12000
A80: 1405/05/04 | C80: 3206133 | D80: ECU S4 4coil Without Vent تکمیل کاری شده | E80: =VLOOKUP(C80,Table1[],3,0) -> ECU S4 4coil | F80: =VLOOKUP(C80,Table1[],4,0) -> ECU مونتاژی | G80: =VLOOKUP(C80,Table1[],5,0) -> ECU S4 4coil | H80: =VLOOKUP(C80,Table1[],6,0) -> EMS-توسعه و نگاشت موتور | I80: تکمیل کاری ECU | J80: - | K80: - | L80: 0 | M80: 800 | N80: EMS | O80: - | P80: - | Q80: - | R80: - | S80: - | T80: - | U80: - | V80: - | W80: - | X80: - | Y80: - | Z80: - | AA80: - | AB80: - | AC80: 0 | AD80: 0 | AE80: 0 | AF80: 0 | AG80: 0 | AH80: 0 | AI80: 44000 | AJ80: - | AK80: - | AL80: - | AM80: - | AN80: - | AO80: - | AP80: - | AQ80: - | AR80: - | AS80: فرآیندی | AT80: - | AU80: - | AV80: - | AW80: - | AX80: 14000 | AY80: 12000 | AZ80: - | BA80: 14000 | BB80: 12000
A81: 1405/05/05 | C81: 3206133 | D81: ECU S4 4coil Without Vent تکمیل کاری شده | E81: =VLOOKUP(C81,Table1[],3,0) -> ECU S4 4coil | F81: =VLOOKUP(C81,Table1[],4,0) -> ECU مونتاژی | G81: =VLOOKUP(C81,Table1[],5,0) -> ECU S4 4coil | H81: =VLOOKUP(C81,Table1[],6,0) -> EMS-توسعه و نگاشت موتور | I81: تکمیل کاری ECU | J81: - | K81: - | L81: 0 | M81: 780 | N81: EMS | O81: - | P81: - | Q81: - | R81: - | S81: - | T81: - | U81: - | V81: - | W81: - | X81: - | Y81: - | Z81: - | AA81: - | AB81: - | AC81: 0 | AD81: 0 | AE81: 0 | AF81: 0 | AG81: 0 | AH81: 0 | AI81: 44000 | AJ81: - | AK81: - | AL81: - | AM81: - | AN81: - | AO81: - | AP81: - | AQ81: - | AR81: - | AS81: فرآیندی | AT81: - | AU81: - | AV81: - | AW81: - | AX81: 14000 | AY81: 12000 | AZ81: - | BA81: 14000 | BB81: 12000
A82: 1405/05/06 | C82: 3206133 | D82: ECU S4 4coil Without Vent تکمیل کاری شده | E82: =VLOOKUP(C82,Table1[],3,0) -> ECU S4 4coil | F82: =VLOOKUP(C82,Table1[],4,0) -> ECU مونتاژی | G82: =VLOOKUP(C82,Table1[],5,0) -> ECU S4 4coil | H82: =VLOOKUP(C82,Table1[],6,0) -> EMS-توسعه و نگاشت موتور | I82: تکمیل کاری ECU | J82: - | K82: - | L82: 0 | M82: 800 | N82: EMS | O82: - | P82: - | Q82: - | R82: - | S82: - | T82: - | U82: - | V82: - | W82: - | X82: - | Y82: - | Z82: - | AA82: - | AB82: - | AC82: 0 | AD82: 0 | AE82: 0 | AF82: 0 | AG82: 0 | AH82: 0 | AI82: 44000 | AJ82: - | AK82: - | AL82: - | AM82: - | AN82: - | AO82: - | AP82: - | AQ82: - | AR82: - | AS82: فرآیندی | AT82: - | AU82: - | AV82: - | AW82: - | AX82: 14000 | AY82: 12000 | AZ82: - | BA82: 14000 | BB82: 12000
A83: 1405/05/07 | C83: 3206133 | D83: ECU S4 4coil Without Vent تکمیل کاری شده | E83: =VLOOKUP(C83,Table1[],3,0) -> ECU S4 4coil | F83: =VLOOKUP(C83,Table1[],4,0) -> ECU مونتاژی | G83: =VLOOKUP(C83,Table1[],5,0) -> ECU S4 4coil | H83: =VLOOKUP(C83,Table1[],6,0) -> EMS-توسعه و نگاشت موتور | I83: تکمیل کاری ECU | J83: - | K83: - | L83: 0 | M83: 800 | N83: EMS | O83: - | P83: - | Q83: - | R83: - | S83: - | T83: - | U83: - | V83: - | W83: - | X83: - | Y83: - | Z83: - | AA83: - | AB83: - | AC83: 0 | AD83: 0 | AE83: 0 | AF83: 0 | AG83: 0 | AH83: 0 | AI83: 44000 | AJ83: - | AK83: - | AL83: - | AM83: - | AN83: - | AO83: - | AP83: - | AQ83: - | AR83: - | AS83: فرآیندی | AT83: - | AU83: - | AV83: - | AW83: - | AX83: 14000 | AY83: 12000 | AZ83: - | BA83: 14000 | BB83: 12000
A84: 1405/05/08 | C84: 3206133 | D84: ECU S4 4coil Without Vent تکمیل کاری شده | E84: =VLOOKUP(C84,Table1[],3,0) -> ECU S4 4coil | F84: =VLOOKUP(C84,Table1[],4,0) -> ECU مونتاژی | G84: =VLOOKUP(C84,Table1[],5,0) -> ECU S4 4coil | H84: =VLOOKUP(C84,Table1[],6,0) -> EMS-توسعه و نگاشت موتور | I84: تکمیل کاری ECU | J84: - | K84: - | L84: 0 | M84: 553 | N84: EMS | O84: - | P84: - | Q84: - | R84: - | S84: - | T84: - | U84: - | V84: - | W84: - | X84: - | Y84: - | Z84: - | AA84: - | AB84: - | AC84: 0 | AD84: 0 | AE84: 0 | AF84: 0 | AG84: 0 | AH84: 0 | AI84: 44000 | AJ84: - | AK84: - | AL84: - | AM84: - | AN84: - | AO84: - | AP84: - | AQ84: - | AR84: - | AS84: فرآیندی | AT84: - | AU84: - | AV84: - | AW84: - | AX84: 14000 | AY84: 12000 | AZ84: - | BA84: 14000 | BB84: 12000
A85: 1405/05/10 | C85: 3206133 | D85: ECU S4 4coil Without Vent تکمیل کاری شده | E85: =VLOOKUP(C85,Table1[],3,0) -> ECU S4 4coil | F85: =VLOOKUP(C85,Table1[],4,0) -> ECU مونتاژی | G85: =VLOOKUP(C85,Table1[],5,0) -> ECU S4 4coil | H85: =VLOOKUP(C85,Table1[],6,0) -> EMS-توسعه و نگاشت موتور | I85: تکمیل کاری ECU | J85: - | K85: - | L85: 0 | M85: 593 | N85: EMS | O85: - | P85: - | Q85: - | R85: - | S85: - | T85: - | U85: - | V85: - | W85: - | X85: - | Y85: - | Z85: - | AA85: - | AB85: - | AC85: 0 | AD85: 0 | AE85: 0 | AF85: 0 | AG85: 0 | AH85: 0 | AI85: 44000 | AJ85: - | AK85: - | AL85: - | AM85: - | AN85: - | AO85: - | AP85: - | AQ85: - | AR85: - | AS85: فرآیندی | AT85: - | AU85: - | AV85: - | AW85: - | AX85: 14000 | AY85: 12000 | AZ85: - | BA85: 14000 | BB85: 12000
A86: 1405/05/11 | C86: 3206133 | D86: ECU S4 4coil Without Vent تکمیل کاری شده | E86: =VLOOKUP(C86,Table1[],3,0) -> ECU S4 4coil | F86: =VLOOKUP(C86,Table1[],4,0) -> ECU مونتاژی | G86: =VLOOKUP(C86,Table1[],5,0) -> ECU S4 4coil | H86: =VLOOKUP(C86,Table1[],6,0) -> EMS-توسعه و نگاشت موتور | I86: تکمیل کاری ECU | J86: - | K86: - | L86: 0 | M86: 800 | N86: EMS | O86: - | P86: - | Q86: - | R86: - | S86: - | T86: - | U86: - | V86: - | W86: - | X86: - | Y86: - | Z86: - | AA86: - | AB86: - | AC86: 0 | AD86: 0 | AE86: 0 | AF86: 0 | AG86: 0 | AH86: 0 | AI86: 44000 | AJ86: - | AK86: - | AL86: - | AM86: - | AN86: - | AO86: - | AP86: - | AQ86: - | AR86: - | AS86: فرآیندی | AT86: - | AU86: - | AV86: - | AW86: - | AX86: 14000 | AY86: 12000 | AZ86: - | BA86: 14000 | BB86: 12000
A87: 1405/05/12 | C87: 3206133 | D87: ECU S4 4coil Without Vent تکمیل کاری شده | E87: =VLOOKUP(C87,Table1[],3,0) -> ECU S4 4coil | F87: =VLOOKUP(C87,Table1[],4,0) -> ECU مونتاژی | G87: =VLOOKUP(C87,Table1[],5,0) -> ECU S4 4coil | H87: =VLOOKUP(C87,Table1[],6,0) -> EMS-توسعه و نگاشت موتور | I87: تکمیل کاری ECU | J87: - | K87: - | L87: 0 | M87: 600 | N87: EMS | O87: - | P87: - | Q87: - | R87: - | S87: - | T87: - | U87: - | V87: - | W87: - | X87: - | Y87: - | Z87: - | AA87: - | AB87: - | AC87: 0 | AD87: 0 | AE87: 0 | AF87: 0 | AG87: 0 | AH87: 0 | AI87: 44000 | AJ87: - | AK87: - | AL87: - | AM87: - | AN87: - | AO87: - | AP87: - | AQ87: - | AR87: - | AS87: فرآیندی | AT87: - | AU87: - | AV87: - | AW87: - | AX87: 14000 | AY87: 12000 | AZ87: - | BA87: 14000 | BB87: 12000
A88: 1405/05/24 | C88: 3206133 | D88: ECU S4 4coil Without Vent تکمیل کاری شده | E88: =VLOOKUP(C88,Table1[],3,0) -> ECU S4 4coil | F88: =VLOOKUP(C88,Table1[],4,0) -> ECU مونتاژی | G88: =VLOOKUP(C88,Table1[],5,0) -> ECU S4 4coil | H88: =VLOOKUP(C88,Table1[],6,0) -> EMS-توسعه و نگاشت موتور | I88: تکمیل کاری ECU | J88: - | K88: - | L88: 0 | M88: 593 | N88: EMS | O88: - | P88: - | Q88: - | R88: - | S88: - | T88: - | U88: - | V88: - | W88: - | X88: - | Y88: - | Z88: - | AA88: - | AB88: - | AC88: 0 | AD88: 0 | AE88: 0 | AF88: 0 | AG88: 0 | AH88: 0 | AI88: 44000 | AJ88: - | AK88: - | AL88: - | AM88: - | AN88: - | AO88: - | AP88: - | AQ88: - | AR88: - | AS88: فرآیندی | AT88: - | AU88: - | AV88: - | AW88: - | AX88: 14000 | AY88: 12000 | AZ88: - | BA88: 14000 | BB88: 12000
A89: 1405/05/25 | C89: 3206133 | D89: ECU S4 4coil Without Vent تکمیل کاری شده | E89: =VLOOKUP(C89,Table1[],3,0) -> ECU S4 4coil | F89: =VLOOKUP(C89,Table1[],4,0) -> ECU مونتاژی | G89: =VLOOKUP(C89,Table1[],5,0) -> ECU S4 4coil | H89: =VLOOKUP(C89,Table1[],6,0) -> EMS-توسعه و نگاشت موتور | I89: تکمیل کاری ECU | J89: - | K89: - | L89: 0 | M89: 578 | N89: EMS | O89: - | P89: - | Q89: - | R89: - | S89: - | T89: - | U89: - | V89: - | W89: - | X89: - | Y89: - | Z89: - | AA89: - | AB89: - | AC89: 0 | AD89: 0 | AE89: 0 | AF89: 0 | AG89: 0 | AH89: 0 | AI89: 44000 | AJ89: - | AK89: - | AL89: - | AM89: - | AN89: - | AO89: - | AP89: - | AQ89: - | AR89: - | AS89: فرآیندی | AT89: - | AU89: - | AV89: - | AW89: - | AX89: 14000 | AY89: 12000 | AZ89: - | BA89: 14000 | BB89: 12000
... A111: 1405/05/31 | C111: 3206134 | D111: تست و کنترل شده ECU S4 4coil Without Vent | E111: =VLOOKUP(C111,Table1[],3,0) -> ECU S4 4coil | F111: =VLOOKUP(C111,Table1[],4,0) -> ECU مونتاژی | G111: =VLOOKUP(C111,Table1[],5,0) -> ECU S4 4coil | H111: =VLOOKUP(C111,Table1[],6,0) -> EMS-توسعه و نگاشت موتور | I111: تست و کنترل ECU | J111: - | K111: - | L111: 0 | M111: 650 | N111: EMS | O111: - | P111: - | Q111: - | R111: - | S111: - | T111: - | U111: - | V111: - | W111: - | X111: - | Y111: - | Z111: - | AA111: - | AB111: - | AC111: 0 | AD111: 0 | AE111: 0 | AF111: 0 | AG111: 0 | AH111: 0 | AI111: 44000 | AJ111: - | AK111: - | AL111: - | AM111: - | AN111: - | AO111: - | AP111: - | AQ111: - | AR111: - | AS111: فرآیندی | AT111: - | AU111: - | AV111: - | AW111: - | AX111: 14000 | AY111: 12000 | AZ111: - | BA111: 14000 | BB111: 12000
A112: 1405/05/04 | B112: شیفت صبح (12 ساعته) | C112: 3206133 | D112: ECU S4 4coil Without Vent تکمیل کاری شده | E112: =VLOOKUP(C112,Table1[],3,0) -> ECU S4 4coil | F112: =VLOOKUP(C112,Table1[],4,0) -> ECU مونتاژی | G112: =VLOOKUP(C112,Table1[],5,0) -> ECU S4 4coil | H112: =VLOOKUP(C112,Table1[],6,0) -> EMS-توسعه و نگاشت موتور | I112: تکمیل کاری ECU | J112: ECU-05 | K112: هرز شدن رزوه قاب بعد از بستن پیچ | L112: 1 | M112: 0 | N112: EMS | O112: - | P112: - | Q112: - | R112: - | S112: - | T112: - | U112: - | V112: - | W112: - | X112: - | Y112: - | Z112: - | AA112: - | AB112: - | AC112: 0 | AD112: 0 | AE112: 0 | AF112: 0 | AG112: 0 | AH112: 0 | AI112: 44000 | AJ112: - | AK112: - | AL112: - | AM112: - | AN112: - | AO112: - | AP112: - | AQ112: - | AR112: - | AS112: فرآیندی | AT112: - | AU112: - | AV112: - | AW112: - | AX112: 14000 | AY112: 12000 | AZ112: - | BA112: 14000 | BB112: 12000
A113: 1405/05/06 | C113: 3206133 | D113: ECU S4 4coil Without Vent تکمیل کاری شده | E113: =VLOOKUP(C113,Table1[],3,0) -> ECU S4 4coil | F113: =VLOOKUP(C113,Table1[],4,0) -> ECU مونتاژی | G113: =VLOOKUP(C113,Table1[],5,0) -> ECU S4 4coil | H113: =VLOOKUP(C113,Table1[],6,0) -> EMS-توسعه و نگاشت موتور | I113: تکمیل کاری ECU | J113: ECU-01 | K113: بسته نشدن کامل پیچ | L113: 3 | M113: 0 | N113: EMS | O113: - | P113: - | Q113: - | R113: - | S113: - | T113: - | U113: - | V113: - | W113: - | X113: - | Y113: - | Z113: - | AA113: - | AB113: - | AC113: 0 | AD113: 0 | AE113: 0 | AF113: 0 | AG113: 0 | AH113: 0 | AI113: 44000 | AJ113: - | AK113: - | AL113: - | AM113: - | AN113: - | AO113: - | AP113: - | AQ113: - | AR113: - | AS113: فرآیندی | AT113: - | AU113: - | AV113: - | AW113: - | AX113: 14000 | AY113: 12000 | AZ113: - | BA113: 14000 | BB113: 12000
A114: 1405/05/06 | B114: شیفت صبح (12 ساعته) | C114: 3206133 | D114: ECU S4 4coil Without Vent تکمیل کاری شده | E114: =VLOOKUP(C114,Table1[],3,0) -> ECU S4 4coil | F114: =VLOOKUP(C114,Table1[],4,0) -> ECU مونتاژی | G114: =VLOOKUP(C114,Table1[],5,0) -> ECU S4 4coil | H114: =VLOOKUP(C114,Table1[],6,0) -> EMS-توسعه و نگاشت موتور | I114: تکمیل کاری ECU | J114: ECU-01 | K114: بسته نشدن کامل پیچ | L114: 3 | M114: 0 | N114: EMS | O114: - | P114: - | Q114: - | R114: - | S114: - | T114: - | U114: - | V114: - | W114: - | X114: - | Y114: - | Z114: - | AA114: - | AB114: - | AC114: 0 | AD114: 0 | AE114: 0 | AF114: 0 | AG114: 0 | AH114: 0 | AI114: 44000 | AJ114: - | AK114: - | AL114: - | AM114: - | AN114: - | AO114: - | AP114: - | AQ114: - | AR114: - | AS114: فرآیندی | AT114: - | AU114: - | AV114: - | AW114: - | AX114: 14000 | AY114: 12000 | AZ114: - | BA114: 14000 | BB114: 12000
A115: 1405/05/10 | B115: شیفت صبح (12 ساعته) | C115: 3206133 | D115: ECU S4 4coil Without Vent تکمیل کاری شده | E115: =VLOOKUP(C115,Table1[],3,0) -> ECU S4 4coil | F115: =VLOOKUP(C115,Table1[],4,0) -> ECU مونتاژی | G115: =VLOOKUP(C115,Table1[],5,0) -> ECU S4 4coil | H115: =VLOOKUP(C115,Table1[],6,0) -> EMS-توسعه و نگاشت موتور | I115: تکمیل کاری ECU | J115: ECU-05 | K115: هرز شدن رزوه قاب بعد از بستن پیچ | L115: 2 | M115: 0 | N115: EMS | O115: - | P115: - | Q115: - | R115: - | S115: - | T115: - | U115: - | V115: - | W115: - | X115: - | Y115: - | Z115: - | AA115: - | AB115: - | AC115: 0 | AD115: 0 | AE115: 0 | AF115: 0 | AG115: 0 | AH115: 0 | AI115: 44000 | AJ115: - | AK115: - | AL115: - | AM115: - | AN115: - | AO115: - | AP115: - | AQ115: - | AR115: - | AS115: فرآیندی | AT115: - | AU115: - | AV115: - | AW115: - | AX115: 14000 | AY115: 12000 | AZ115: - | BA115: 14000 | BB115: 12000
A116: 1405/05/25 | B116: شیفت صبح (12 ساعته) | C116: 3206133 | D116: ECU S4 4coil Without Vent تکمیل کاری شده | E116: =VLOOKUP(C116,Table1[],3,0) -> ECU S4 4coil | F116: =VLOOKUP(C116,Table1[],4,0) -> ECU مونتاژی | G116: =VLOOKUP(C116,Table1[],5,0) -> ECU S4 4coil | H116: =VLOOKUP(C116,Table1[],6,0) -> EMS-توسعه و نگاشت موتور | I116: تکمیل کاری ECU | J116: ECU-01 | K116: بسته نشدن کامل پیچ | L116: 2 | M116: 0 | N116: EMS | O116: - | P116: - | Q116: - | R116: - | S116: - | T116: - | U116: - | V116: - | W116: - | X116: - | Y116: - | Z116: - | AA116: - | AB116: - | AC116: 0 | AD116: 0 | AE116: 0 | AF116: 0 | AG116: 0 | AH116: 0 | AI116: 44000 | AJ116: - | AK116: - | AL116: - | AM116: - | AN116: - | AO116: - | AP116: - | AQ116: - | AR116: - | AS116: فرآیندی | AT116: - | AU116: - | AV116: - | AW116: - | AX116: 14000 | AY116: 12000 | AZ116: - | BA116: 14000 | BB116: 12000
A117: 1405/05/01 | B117: اضافه کار | C117: 3206134 | D117: تست و کنترل شده ECU S4 4coil Without Vent | E117: =VLOOKUP(C117,Table1[],3,0) -> ECU S4 4coil | F117: =VLOOKUP(C117,Table1[],4,0) -> ECU مونتاژی | G117: =VLOOKUP(C117,Table1[],5,0) -> ECU S4 4coil | H117: =VLOOKUP(C117,Table1[],6,0) -> EMS-توسعه و نگاشت موتور | I117: تست و کنترل ECU | J117: FTD-750 | K117: نشتی دور قاب | L117: 1 | M117: 0 | N117: EMS | O117: - | P117: - | Q117: - | R117: - | S117: - | T117: - | U117: - | V117: - | W117: - | X117: - | Y117: - | Z117: - | AA117: - | AB117: - | AC117: 0 | AD117: 0 | AE117: 0 | AF117: 0 | AG117: 0 | AH117: 0 | AI117: 44000 | AJ117: - | AK117: - | AL117: - | AM117: - | AN117: - | AO117: - | AP117: - | AQ117: - | AR117: - | AS117: فرآیندی | AT117: - | AU117: - | AV117: - | AW117: - | AX117: 14000 | AY117: 12000 | AZ117: - | BA117: 14000 | BB117: 12000
A118: 1405/05/01 | B118: عادی | C118: 3206134 | D118: تست و کنترل شده ECU S4 4coil Without Vent | E118: =VLOOKUP(C118,Table1[],3,0) -> ECU S4 4coil | F118: =VLOOKUP(C118,Table1[],4,0) -> ECU مونتاژی | G118: =VLOOKUP(C118,Table1[],5,0) -> ECU S4 4coil | H118: =VLOOKUP(C118,Table1[],6,0) -> EMS-توسعه و نگاشت موتور | I118: تست و کنترل ECU | J118: FTD-750 | K118: نشتی دور قاب | L118: 1 | M118: 0 | N118: EMS | O118: - | P118: - | Q118: - | R118: - | S118: - | T118: - | U118: - | V118: - | W118: - | X118: - | Y118: - | Z118: - | AA118: - | AB118: - | AC118: 0 | AD118: 0 | AE118: 0 | AF118: 0 | AG118: 0 | AH118: 0 | AI118: 44000 | AJ118: - | AK118: - | AL118: - | AM118: - | AN118: - | AO118: - | AP118: - | AQ118: - | AR118: - | AS118: فرآیندی | AT118: - | AU118: - | AV118: - | AW118: - | AX118: 14000 | AY118: 12000 | AZ118: - | BA118: 14000 | BB118: 12000
A119: 1405/05/01 | B119: اضافه کار | C119: 3206134 | D119: تست و کنترل شده ECU S4 4coil Without Vent | E119: =VLOOKUP(C119,Table1[],3,0) -> ECU S4 4coil | F119: =VLOOKUP(C119,Table1[],4,0) -> ECU مونتاژی | G119: =VLOOKUP(C119,Table1[],5,0) -> ECU S4 4coil | H119: =VLOOKUP(C119,Table1[],6,0) -> EMS-توسعه و نگاشت موتور | I119: تست و کنترل ECU | J119: FTD-751 | K119: نشتی به علت ترک قاب بالایی | L119: 1 | M119: 0 | N119: EMS | O119: - | P119: - | Q119: - | R119: - | S119: - | T119: - | U119: - | V119: - | W119: - | X119: - | Y119: - | Z119: - | AA119: - | AB119: - | AC119: 0 | AD119: 0 | AE119: 0 | AF119: 0 | AG119: 0 | AH119: 0 | AI119: 44000 | AJ119: - | AK119: - | AL119: - | AM119: - | AN119: - | AO119: - | AP119: - | AQ119: - | AR119: - | AS119: فرآیندی | AT119: - | AU119: - | AV119: - | AW119: - | AX119: 14000 | AY119: 12000 | AZ119: - | BA119: 14000 | BB119: 12000
A120: 1405/05/01 | B120: عادی | C120: 3206134 | D120: تست و کنترل شده ECU S4 4coil Without Vent | E120: =VLOOKUP(C120,Table1[],3,0) -> ECU S4 4coil | F120: =VLOOKUP(C120,Table1[],4,0) -> ECU مونتاژی | G120: =VLOOKUP(C120,Table1[],5,0) -> ECU S4 4coil | H120: =VLOOKUP(C120,Table1[],6,0) -> EMS-توسعه و نگاشت موتور | I120: تست و کنترل ECU | J120: FTD-751 | K120: نشتی به علت ترک قاب بالایی | L120: 1 | M120: 0 | N120: EMS | O120: - | P120: - | Q120: - | R120: - | S120: - | T120: - | U120: - | V120: - | W120: - | X120: - | Y120: - | Z120: - | AA120: - | AB120: - | AC120: 0 | AD120: 0 | AE120: 0 | AF120: 0 | AG120: 0 | AH120: 0 | AI120: 44000 | AJ120: - | AK120: - | AL120: - | AM120: - | AN120: - | AO120: - | AP120: - | AQ120: - | AR120: - | AS120: فرآیندی | AT120: - | AU120: - | AV120: - | AW120: - | AX120: 14000 | AY120: 12000 | AZ120: - | BA120: 14000 | BB120: 12000
A121: 1405/05/01 | B121: اضافه کار | C121: 3206134 | D121: تست و کنترل شده ECU S4 4coil Without Vent | E121: =VLOOKUP(C121,Table1[],3,0) -> ECU S4 4coil | F121: =VLOOKUP(C121,Table1[],4,0) -> ECU مونتاژی | G121: =VLOOKUP(C121,Table1[],5,0) -> ECU S4 4coil | H121: =VLOOKUP(C121,Table1[],6,0) -> EMS-توسعه و نگاشت موتور | I121: تست و کنترل ECU | J121: FTD-752 | K121: نشتی به علت ترک قاب پایینی | L121: 1 | M121: 0 | N121: EMS | O121: - | P121: - | Q121: - | R121: - | S121: - | T121: - | U121: - | V121: - | W121: - | X121: - | Y121: - | Z121: - | AA121: - | AB121: - | AC121: 0 | AD121: 0 | AE121: 0 | AF121: 0 | AG121: 0 | AH121: 0 | AI121: 44000 | AJ121: - | AK121: - | AL121: - | AM121: - | AN121: - | AO121: - | AP121: - | AQ121: - | AR121: - | AS121: فرآیندی | AT121: - | AU121: - | AV121: - | AW121: - | AX121: 14000 | AY121: 12000 | AZ121: - | BA121: 14000 | BB121: 12000
A122: 1405/05/01 | B122: عادی | C122: 3206134 | D122: تست و کنترل شده ECU S4 4coil Without Vent | E122: =VLOOKUP(C122,Table1[],3,0) -> ECU S4 4coil | F122: =VLOOKUP(C122,Table1[],4,0) -> ECU مونتاژی | G122: =VLOOKUP(C122,Table1[],5,0) -> ECU S4 4coil | H122: =VLOOKUP(C122,Table1[],6,0) -> EMS-توسعه و نگاشت موتور | I122: تست و کنترل ECU | J122: FTD-752 | K122: نشتی به علت ترک قاب پایینی | L122: 1 | M122: 0 | N122: EMS | O122: - | P122: - | Q122: - | R122: - | S122: - | T122: - | U122: - | V122: - | W122: - | X122: - | Y122: - | Z122: - | AA122: - | AB122: - | AC122: 0 | AD122: 0 | AE122: 0 | AF122: 0 | AG122: 0 | AH122: 0 | AI122: 44000 | AJ122: - | AK122: - | AL122: - | AM122: - | AN122: - | AO122: - | AP122: - | AQ122: - | AR122: - | AS122: فرآیندی | AT122: - | AU122: - | AV122: - | AW122: - | AX122: 14000 | AY122: 12000 | AZ122: - | BA122: 14000 | BB122: 12000
A123: 1405/05/03 | B123: اضافه کار | C123: 3206134 | D123: تست و کنترل شده ECU S4 4coil Without Vent | E123: =VLOOKUP(C123,Table1[],3,0) -> ECU S4 4coil | F123: =VLOOKUP(C123,Table1[],4,0) -> ECU مونتاژی | G123: =VLOOKUP(C123,Table1[],5,0) -> ECU S4 4coil | H123: =VLOOKUP(C123,Table1[],6,0) -> EMS-توسعه و نگاشت موتور | I123: تست و کنترل ECU | J123: FTD-750 | K123: نشتی دور قاب | L123: 1 | M123: 0 | N123: EMS | O123: - | P123: - | Q123: - | R123: - | S123: - | T123: - | U123: - | V123: - | W123: - | X123: - | Y123: - | Z123: - | AA123: - | AB123: - | AC123: 0 | AD123: 0 | AE123: 0 | AF123: 0 | AG123: 0 | AH123: 0 | AI123: 44000 | AJ123: - | AK123: - | AL123: - | AM123: - | AN123: - | AO123: - | AP123: - | AQ123: - | AR123: - | AS123: فرآیندی | AT123: - | AU123: - | AV123: - | AW123: - | AX123: 14000 | AY123: 12000 | AZ123: - | BA123: 14000 | BB123: 12000
A124: 1405/05/03 | B124: عادی | C124: 3206134 | D124: تست و کنترل شده ECU S4 4coil Without Vent | E124: =VLOOKUP(C124,Table1[],3,0) -> ECU S4 4coil | F124: =VLOOKUP(C124,Table1[],4,0) -> ECU مونتاژی | G124: =VLOOKUP(C124,Table1[],5,0) -> ECU S4 4coil | H124: =VLOOKUP(C124,Table1[],6,0) -> EMS-توسعه و نگاشت موتور | I124: تست و کنترل ECU | J124: FTD-750 | K124: نشتی دور قاب | L124: 1 | M124: 0 | N124: EMS | O124: - | P124: - | Q124: - | R124: - | S124: - | T124: - | U124: - | V124: - | W124: - | X124: - | Y124: - | Z124: - | AA124: - | AB124: - | AC124: 0 | AD124: 0 | AE124: 0 | AF124: 0 | AG124: 0 | AH124: 0 | AI124: 44000 | AJ124: - | AK124: - | AL124: - | AM124: - | AN124: - | AO124: - | AP124: - | AQ124: - | AR124: - | AS124: فرآیندی | AT124: - | AU124: - | AV124: - | AW124: - | AX124: 14000 | AY124: 12000 | AZ124: - | BA124: 14000 | BB124: 12000
...

Sheet QC EMS
A1: تاریخ | B1: شیفت کاری | C1: کد گروه محصول | D1: کد محصول | E1: نام محصول | F1: خانواده محصول | G1: نام محصول ترکیبی | H1: گروه محصول نهایی | I1: ایستگاه | J1: کد ایراد | K1: شرح ایراد | L1: تعداد ایراد | M1: تعداد کل | N1: برنچ | O1: شرح فعالیت انجام شده توسط تعمیرات | P1: عامل مسبب ایراد 6M | Q1: کد قطعه | R1: نام قطعه | S1: نام تامین کننده | T1: کد و نام تجهیزات و ابزارآلات | U1: کد تجهیزات و ابزارآلات | V1: کد و نام تجهیزات و ابزارآلات1 | W1: کد فرآیند (OPC) | X1: نام فرآیند (OPC) | Y1: حالت خرابی بالقوه | Z1: نوع حالت خرابی بالقوه | AA1: توضیحات تعمیرات | AB1: ستون مشترک حالت خرابی | AC1: شدت حالت خرابی | AD1: تشخیص حالت خرابی | AE1: وقوع قدیمی | AF1: مدت زمان عیب یابی ( دقیقه ) | AG1: مدت زمان رفع عیب ( دقیقه ) | AH1: مدت زمان تست مجدد ( دقیقه ) | AI1: هزینه ریالی تعمیرات | AJ1: خانواده قطعات | AK1: شماره BOM | AL1: شماره برگ ارسال | AM1: کد اپراتور | AN1: نام اپراتور | AO1: کد بازرس چشمی | AP1: نام بازرس | AQ1: AOI | AR1: نام بازرس AOI | AS1: نوع قطعات تولیدی و تامینی | AT1: وضعیت اعلام ایرادات | AU1: توضیحات اضافه | AV1: توضیحات | AW1: Control Station | AX1: حد قابل قبول | AY1: هدف | AZ1: علت افت یا بهبود PPM | BA1: حد قابل قبول عظام | BB1: هدف عظام
A2: 1405/05/03 | B2: - | C2: 3311018 | D2: مجموعه رایانه موتور بنزینی ECU S4 XU7P SOREN (SBCM) | E2: =VLOOKUP(C2,Table1[],3,0) -> ECU S4 XUP SBCM | F2: =VLOOKUP(C2,Table1[],4,0) -> ECU مونتاژی | G2: =VLOOKUP(C2,Table1[],5,0) -> Ecu S4 32Bit Semifinal | H2: =VLOOKUP(C2,Table1[],6,0) -> EMS-توسعه و نگاشت موتور | I2: کنترل نهایی | J2: - | K2: - | L2: 0 | M2: 288 | N2: =VLOOKUP(C2,Table1[],7,0) -> EMS | O2: - | P2: - | Q2: - | R2: - | S2: - | T2: - | U2: - | V2: - | W2: - | X2: - | Y2: - | Z2: - | AA2: - | AB2: - | AC2: 0 | AD2: 0 | AE2: 0 | AF2: 0 | AG2: 0 | AH2: 0 | AI2: 44000 | AJ2: - | AK2: - | AL2: - | AM2: - | AN2: - | AO2: - | AP2: - | AQ2: - | AR2: - | AS2: فرآیندی | AT2: - | AU2: - | AV2: - | AW2: - | AX2: 14000 | AY2: 12000 | AZ2: - | BA2: 14000 | BB2: 12000
A3: 1405/05/04 | B3: - | C3: 3311018 | D3: مجموعه رایانه موتور بنزینی ECU S4 XU7P SOREN (SBCM) | E3: =VLOOKUP(C3,Table1[],3,0) -> ECU S4 XUP SBCM | F3: =VLOOKUP(C3,Table1[],4,0) -> ECU مونتاژی | G3: =VLOOKUP(C3,Table1[],5,0) -> Ecu S4 32Bit Semifinal | H3: =VLOOKUP(C3,Table1[],6,0) -> EMS-توسعه و نگاشت موتور | I3: کنترل نهایی | J3: - | K3: - | L3: 0 | M3: 288 | N3: =VLOOKUP(C3,Table1[],7,0) -> EMS | O3: - | P3: - | Q3: - | R3: - | S3: - | T3: - | U3: - | V3: - | W3: - | X3: - | Y3: - | Z3: - | AA3: - | AB3: - | AC3: 0 | AD3: 0 | AE3: 0 | AF3: 0 | AG3: 0 | AH3: 0 | AI3: 44000 | AJ3: - | AK3: - | AL3: - | AM3: - | AN3: - | AO3: - | AP3: - | AQ3: - | AR3: - | AS3: فرآیندی | AT3: - | AU3: - | AV3: - | AW3: - | AX3: 14000 | AY3: 12000 | AZ3: - | BA3: 14000 | BB3: 12000
A4: 1405/05/05 | B4: - | C4: 3311018 | D4: مجموعه رایانه موتور بنزینی ECU S4 XU7P SOREN (SBCM) | E4: =VLOOKUP(C4,Table1[],3,0) -> ECU S4 XUP SBCM | F4: =VLOOKUP(C4,Table1[],4,0) -> ECU مونتاژی | G4: =VLOOKUP(C4,Table1[],5,0) -> Ecu S4 32Bit Semifinal | H4: =VLOOKUP(C4,Table1[],6,0) -> EMS-توسعه و نگاشت موتور | I4: کنترل نهایی | J4: - | K4: - | L4: 0 | M4: 224 | N4: =VLOOKUP(C4,Table1[],7,0) -> EMS | O4: - | P4: - | Q4: - | R4: - | S4: - | T4: - | U4: - | V4: - | W4: - | X4: - | Y4: - | Z4: - | AA4: - | AB4: - | AC4: 0 | AD4: 0 | AE4: 0 | AF4: 0 | AG4: 0 | AH4: 0 | AI4: 44000 | AJ4: - | AK4: - | AL4: - | AM4: - | AN4: - | AO4: - | AP4: - | AQ4: - | AR4: - | AS4: فرآیندی | AT4: - | AU4: - | AV4: - | AW4: - | AX4: 14000 | AY4: 12000 | AZ4: - | BA4: 14000 | BB4: 12000
A5: 1405/05/06 | B5: - | C5: 3311018 | D5: مجموعه رایانه موتور بنزینی ECU S4 XU7P SOREN (SBCM) | E5: =VLOOKUP(C5,Table1[],3,0) -> ECU S4 XUP SBCM | F5: =VLOOKUP(C5,Table1[],4,0) -> ECU مونتاژی | G5: =VLOOKUP(C5,Table1[],5,0) -> Ecu S4 32Bit Semifinal | H5: =VLOOKUP(C5,Table1[],6,0) -> EMS-توسعه و نگاشت موتور | I5: کنترل نهایی | J5: - | K5: - | L5: 0 | M5: 288 | N5: =VLOOKUP(C5,Table1[],7,0) -> EMS | O5: - | P5: - | Q5: - | R5: - | S5: - | T5: - | U5: - | V5: - | W5: - | X5: - | Y5: - | Z5: - | AA5: - | AB5: - | AC5: 0 | AD5: 0 | AE5: 0 | AF5: 0 | AG5: 0 | AH5: 0 | AI5: 44000 | AJ5: - | AK5: - | AL5: - | AM5: - | AN5: - | AO5: - | AP5: - | AQ5: - | AR5: - | AS5: فرآیندی | AT5: - | AU5: - | AV5: - | AW5: - | AX5: 14000 | AY5: 12000 | AZ5: - | BA5: 14000 | BB5: 12000
A6: 1405/05/07 | B6: - | C6: 3311018 | D6: مجموعه رایانه موتور بنزینی ECU S4 XU7P SOREN (SBCM) | E6: =VLOOKUP(C6,Table1[],3,0) -> ECU S4 XUP SBCM | F6: =VLOOKUP(C6,Table1[],4,0) -> ECU مونتاژی | G6: =VLOOKUP(C6,Table1[],5,0) -> Ecu S4 32Bit Semifinal | H6: =VLOOKUP(C6,Table1[],6,0) -> EMS-توسعه و نگاشت موتور | I6: کنترل نهایی | J6: - | K6: - | L6: 0 | M6: 224 | N6: =VLOOKUP(C6,Table1[],7,0) -> EMS | O6: - | P6: - | Q6: - | R6: - | S6: - | T6: - | U6: - | V6: - | W6: - | X6: - | Y6: - | Z6: - | AA6: - | AB6: - | AC6: 0 | AD6: 0 | AE6: 0 | AF6: 0 | AG6: 0 | AH6: 0 | AI6: 44000 | AJ6: - | AK6: - | AL6: - | AM6: - | AN6: - | AO6: - | AP6: - | AQ6: - | AR6: - | AS6: فرآیندی | AT6: - | AU6: - | AV6: - | AW6: - | AX6: 14000 | AY6: 12000 | AZ6: - | BA6: 14000 | BB6: 12000
A7: 1405/05/08 | B7: - | C7: 3311018 | D7: مجموعه رایانه موتور بنزینی ECU S4 XU7P SOREN (SBCM) | E7: =VLOOKUP(C7,Table1[],3,0) -> ECU S4 XUP SBCM | F7: =VLOOKUP(C7,Table1[],4,0) -> ECU مونتاژی | G7: =VLOOKUP(C7,Table1[],5,0) -> Ecu S4 32Bit Semifinal | H7: =VLOOKUP(C7,Table1[],6,0) -> EMS-توسعه و نگاشت موتور | I7: کنترل نهایی | J7: - | K7: - | L7: 0 | M7: 400 | N7: =VLOOKUP(C7,Table1[],7,0) -> EMS | O7: - | P7: - | Q7: - | R7: - | S7: - | T7: - | U7: - | V7: - | W7: - | X7: - | Y7: - | Z7: - | AA7: - | AB7: - | AC7: 0 | AD7: 0 | AE7: 0 | AF7: 0 | AG7: 0 | AH7: 0 | AI7: 44000 | AJ7: - | AK7: - | AL7: - | AM7: - | AN7: - | AO7: - | AP7: - | AQ7: - | AR7: - | AS7: فرآیندی | AT7: - | AU7: - | AV7: - | AW7: - | AX7: 14000 | AY7: 12000 | AZ7: - | BA7: 14000 | BB7: 12000
A8: 1405/05/10 | B8: - | C8: 3311018 | D8: مجموعه رایانه موتور بنزینی ECU S4 XU7P SOREN (SBCM) | E8: =VLOOKUP(C8,Table1[],3,0) -> ECU S4 XUP SBCM | F8: =VLOOKUP(C8,Table1[],4,0) -> ECU مونتاژی | G8: =VLOOKUP(C8,Table1[],5,0) -> Ecu S4 32Bit Semifinal | H8: =VLOOKUP(C8,Table1[],6,0) -> EMS-توسعه و نگاشت موتور | I8: کنترل نهایی | J8: - | K8: - | L8: 0 | M8: 24 | N8: =VLOOKUP(C8,Table1[],7,0) -> EMS | O8: - | P8: - | Q8: - | R8: - | S8: - | T8: - | U8: - | V8: - | W8: - | X8: - | Y8: - | Z8: - | AA8: - | AB8: - | AC8: 0 | AD8: 0 | AE8: 0 | AF8: 0 | AG8: 0 | AH8: 0 | AI8: 44000 | AJ8: - | AK8: - | AL8: - | AM8: - | AN8: - | AO8: - | AP8: - | AQ8: - | AR8: - | AS8: فرآیندی | AT8: - | AU8: - | AV8: - | AW8: - | AX8: 14000 | AY8: 12000 | AZ8: - | BA8: 14000 | BB8: 12000
A9: 1405/05/11 | B9: - | C9: 3311018 | D9: مجموعه رایانه موتور بنزینی ECU S4 XU7P SOREN (SBCM) | E9: =VLOOKUP(C9,Table1[],3,0) -> ECU S4 XUP SBCM | F9: =VLOOKUP(C9,Table1[],4,0) -> ECU مونتاژی | G9: =VLOOKUP(C9,Table1[],5,0) -> Ecu S4 32Bit Semifinal | H9: =VLOOKUP(C9,Table1[],6,0) -> EMS-توسعه و نگاشت موتور | I9: کنترل نهایی | J9: - | K9: - | L9: 0 | M9: 224 | N9: =VLOOKUP(C9,Table1[],7,0) -> EMS | O9: - | P9: - | Q9: - | R9: - | S9: - | T9: - | U9: - | V9: - | W9: - | X9: - | Y9: - | Z9: - | AA9: - | AB9: - | AC9: 0 | AD9: 0 | AE9: 0 | AF9: 0 | AG9: 0 | AH9: 0 | AI9: 44000 | AJ9: - | AK9: - | AL9: - | AM9: - | AN9: - | AO9: - | AP9: - | AQ9: - | AR9: - | AS9: فرآیندی | AT9: - | AU9: - | AV9: - | AW9: - | AX9: 14000 | AY9: 12000 | AZ9: - | BA9: 14000 | BB9: 12000
A10: 1405/05/12 | B10: - | C10: 3311018 | D10: مجموعه رایانه موتور بنزینی ECU S4 XU7P SOREN (SBCM) | E10: =VLOOKUP(C10,Table1[],3,0) -> ECU S4 XUP SBCM | F10: =VLOOKUP(C10,Table1[],4,0) -> ECU مونتاژی | G10: =VLOOKUP(C10,Table1[],5,0) -> Ecu S4 32Bit Semifinal | H10: =VLOOKUP(C10,Table1[],6,0) -> EMS-توسعه و نگاشت موتور | I10: کنترل نهایی | J10: - | K10: - | L10: 0 | M10: 24 | N10: =VLOOKUP(C10,Table1[],7,0) -> EMS | O10: - | P10: - | Q10: - | R10: - | S10: - | T10: - | U10: - | V10: - | W10: - | X10: - | Y10: - | Z10: - | AA10: - | AB10: - | AC10: 0 | AD10: 0 | AE10: 0 | AF10: 0 | AG10: 0 | AH10: 0 | AI10: 44000 | AJ10: - | AK10: - | AL10: - | AM10: - | AN10: - | AO10: - | AP10: - | AQ10: - | AR10: - | AS10: فرآیندی | AT10: - | AU10: - | AV10: - | AW10: - | AX10: 14000 | AY10: 12000 | AZ10: - | BA10: 14000 | BB10: 12000
A11: 1405/05/24 | B11: - | C11: 3311018 | D11: مجموعه رایانه موتور بنزینی ECU S4 XU7P SOREN (SBCM) | E11: =VLOOKUP(C11,Table1[],3,0) -> ECU S4 XUP SBCM | F11: =VLOOKUP(C11,Table1[],4,0) -> ECU مونتاژی | G11: =VLOOKUP(C11,Table1[],5,0) -> Ecu S4 32Bit Semifinal | H11: =VLOOKUP(C11,Table1[],6,0) -> EMS-توسعه و نگاشت موتور | I11: کنترل نهایی | J11: - | K11: - | L11: 0 | M11: 288 | N11: =VLOOKUP(C11,Table1[],7,0) -> EMS | O11: - | P11: - | Q11: - | R11: - | S11: - | T11: - | U11: - | V11: - | W11: - | X11: - | Y11: - | Z11: - | AA11: - | AB11: - | AC11: 0 | AD11: 0 | AE11: 0 | AF11: 0 | AG11: 0 | AH11: 0 | AI11: 44000 | AJ11: - | AK11: - | AL11: - | AM11: - | AN11: - | AO11: - | AP11: - | AQ11: - | AR11: - | AS11: فرآیندی | AT11: - | AU11: - | AV11: - | AW11: - | AX11: 14000 | AY11: 12000 | AZ11: - | BA11: 14000 | BB11: 12000
A12: 1405/05/25 | B12: - | C12: 3311018 | D12: مجموعه رایانه موتور بنزینی ECU S4 XU7P SOREN (SBCM) | E12: =VLOOKUP(C12,Table1[],3,0) -> ECU S4 XUP SBCM | F12: =VLOOKUP(C12,Table1[],4,0) -> ECU مونتاژی | G12: =VLOOKUP(C12,Table1[],5,0) -> Ecu S4 32Bit Semifinal | H12: =VLOOKUP(C12,Table1[],6,0) -> EMS-توسعه و نگاشت موتور | I12: کنترل نهایی | J12: - | K12: - | L12: 0 | M12: 288 | N12: =VLOOKUP(C12,Table1[],7,0) -> EMS | O12: - | P12: - | Q12: - | R12: - | S12: - | T12: - | U12: - | V12: - | W12: - | X12: - | Y12: - | Z12: - | AA12: - | AB12: - | AC12: 0 | AD12: 0 | AE12: 0 | AF12: 0 | AG12: 0 | AH12: 0 | AI12: 44000 | AJ12: - | AK12: - | AL12: - | AM12: - | AN12: - | AO12: - | AP12: - | AQ12: - | AR12: - | AS12: فرآیندی | AT12: - | AU12: - | AV12: - | AW12: - | AX12: 14000 | AY12: 12000 | AZ12: - | BA12: 14000 | BB12: 12000
A13: 1405/05/26 | B13: - | C13: 3311018 | D13: مجموعه رایانه موتور بنزینی ECU S4 XU7P SOREN (SBCM) | E13: =VLOOKUP(C13,Table1[],3,0) -> ECU S4 XUP SBCM | F13: =VLOOKUP(C13,Table1[],4,0) -> ECU مونتاژی | G13: =VLOOKUP(C13,Table1[],5,0) -> Ecu S4 32Bit Semifinal | H13: =VLOOKUP(C13,Table1[],6,0) -> EMS-توسعه و نگاشت موتور | I13: کنترل نهایی | J13: - | K13: - | L13: 0 | M13: 288 | N13: =VLOOKUP(C13,Table1[],7,0) -> EMS | O13: - | P13: - | Q13: - | R13: - | S13: - | T13: - | U13: - | V13: - | W13: - | X13: - | Y13: - | Z13: - | AA13: - | AB13: - | AC13: 0 | AD13: 0 | AE13: 0 | AF13: 0 | AG13: 0 | AH13: 0 | AI13: 44000 | AJ13: - | AK13: - | AL13: - | AM13: - | AN13: - | AO13: - | AP13: - | AQ13: - | AR13: - | AS13: فرآیندی | AT13: - | AU13: - | AV13: - | AW13: - | AX13: 14000 | AY13: 12000 | AZ13: - | BA13: 14000 | BB13: 12000
... A236: 1405/05/31 | B236: - | C236: 3206133 | D236: ECU S4 4coil Without Vent تکمیل کاری شده | E236: =VLOOKUP(C236,Table1[],3,0) -> ECU S4 4coil | F236: =VLOOKUP(C236,Table1[],4,0) -> ECU مونتاژی | G236: =VLOOKUP(C236,Table1[],5,0) -> ECU S4 4coil | H236: =VLOOKUP(C236,Table1[],6,0) -> EMS-توسعه و نگاشت موتور | I236: کنترل نهایی | J236: ECU-07 | K236: کار نمی کند | L236: 3 | M236: 0 | N236: =VLOOKUP(C236,Table1[],7,0) -> EMS | O236: - | P236: تجهیرات و ماشین آلات | Q236: 3121411 | R236: ECU S4 4coil PCBA | S236: - | T236: - | U236: - | V236: - | W236: - | X236: - | Y236: - | Z236: - | AA236: - | AB236: - | AC236: 0 | AD236: 0 | AE236: 0 | AF236: 0 | AG236: 0 | AH236: 0 | AI236: 44000 | AJ236: برد | AK236: - | AL236: - | AM236: - | AN236: - | AO236: - | AP236: - | AQ236: - | AR236: - | AS236: فرآیندی | AT236: - | AU236: - | AV236: - | AW236: - | AX236: 14000 | AY236: 12000 | AZ236: - | BA236: 14000 | BB236: 12000
A237: 1405/05/25 | C237: 3328509 | D237: سنسور ABS عقب چپ 405 و سمند یوفین - دیسکی | E237: =VLOOKUP(C237,Table1[],3,0) -> سنسور ABS عقب چپ 405 و سمند یوفین - دیسکی | F237: =VLOOKUP(C237,Table1[],4,0) -> سنسور ABS | G237: =VLOOKUP(C237,Table1[],5,0) -> سنسور ABS عقب چپ دیسکی 405 یوفین | H237: =VLOOKUP(C237,Table1[],6,0) -> SBS-سیستم های ایمنی ترمز | I237: کنترل نهایی | J237: AD-704 | K237: شکل ظاهری نامناسب تزریق اسکتون | L237: 6 | M237: 0 | N237: =VLOOKUP(C237,Table1[],7,0) -> EMS | O237: - | P237: - | Q237: - | R237: - | S237: - | T237: - | U237: - | V237: - | W237: - | X237: - | Y237: - | Z237: - | AA237: - | AB237: - | AC237: 0 | AD237: 0 | AE237: 0 | AF237: 0 | AG237: 0 | AH237: 0 | AI237: 44000 | AJ237: برد | AK237: - | AL237: - | AM237: - | AN237: - | AO237: - | AP237: - | AQ237: - | AR237: - | AS237: فرآیندی | AT237: - | AU237: - | AV237: - | AW237: - | AX237: 14000 | AY237: 12000 | AZ237: - | BA237: 14000 | BB237: 12000
A238: 1405/05/26 | B238: عادی | C238: 3328510 | D238: سنسور ABS عقب راست 405 و سمند یوفین - دیسکی | E238: =VLOOKUP(C238,Table1[],3,0) -> سنسور ABS عقب راست 405 و سمند یوفین - دیسکی | F238: =VLOOKUP(C238,Table1[],4,0) -> سنسور ABS | G238: =VLOOKUP(C238,Table1[],5,0) -> سنسور ABS عقب راست دیسکی سمند/405 | H238: =VLOOKUP(C238,Table1[],6,0) -> SBS-سیستم های ایمنی ترمز | I238: کنترل نهایی | J238: AD-704 | K238: شکل ظاهری نامناسب تزریق اسکتون | L238: 10 | M238: 1 | N238: =VLOOKUP(C238,Table1[],7,0) -> EMS | O238: - | P238: - | Q238: - | R238: - | S238: - | T238: - | U238: - | V238: - | W238: - | X238: - | Y238: - | Z238: - | AA238: - | AB238: - | AC238: 0 | AD238: 0 | AE238: 0 | AF238: 0 | AG238: 0 | AH238: 0 | AI238: 44000 | AJ238: برد | AK238: - | AL238: - | AM238: - | AN238: - | AO238: - | AP238: - | AQ238: - | AR238: - | AS238: فرآیندی | AT238: - | AU238: - | AV238: - | AW238: - | AX238: 14000 | AY238: 12000 | AZ238: - | BA238: 14000 | BB238: 12000
A239: 1405/05/25 | B239: عادی | C239: 3323001 | D239: کارت حاوی کد دسترسی SSAT - ETC | E239: =VLOOKUP(C239,Table1[],3,0) -> کارت حاوی کد دسترسی SSAT ETC | F239: =VLOOKUP(C239,Table1[],4,0) -> کارت حاوی کد دسترسی | G239: =VLOOKUP(C239,Table1[],5,0) -> کارت حاوی کد دسترسی SSAT ETC | H239: =VLOOKUP(C239,Table1[],6,0) -> EMS-توسعه و نگاشت موتور | I239: کنترل نهایی | J239: AD-748 | K239: عدم تطابق اطلاعات لیبل شناسایی و ردیابی با محصول | L239: 1 | M239: 2 | N239: =VLOOKUP(C239,Table1[],7,0) -> EMS | O239: - | P239: - | Q239: - | R239: - | S239: - | T239: - | U239: - | V239: - | W239: - | X239: - | Y239: - | Z239: - | AA239: - | AB239: - | AC239: 0 | AD239: 0 | AE239: 0 | AF239: 0 | AG239: 0 | AH239: 0 | AI239: 44000 | AJ239: برد | AK239: - | AL239: - | AM239: - | AN239: - | AO239: - | AP239: - | AQ239: - | AR239: - | AS239: فرآیندی | AT239: - | AU239: - | AV239: - | AW239: - | AX239: 14000 | AY239: 12000 | AZ239: - | BA239: 14000 | BB239: 12000
A240: 1405/05/28 | B240: عادی | C240: 3328509 | D240: سنسور ABS عقب چپ 405 و سمند یوفین - دیسکی | E240: =VLOOKUP(C240,Table1[],3,0) -> سنسور ABS عقب چپ 405 و سمند یوفین - دیسکی | F240: =VLOOKUP(C240,Table1[],4,0) -> سنسور ABS | G240: =VLOOKUP(C240,Table1[],5,0) -> سنسور ABS عقب چپ دیسکی 405 یوفین | H240: =VLOOKUP(C240,Table1[],6,0) -> SBS-سیستم های ایمنی ترمز | I240: کنترل نهایی | J240: AD-704 | K240: شکل ظاهری نامناسب تزریق اسکتون | L240: 6 | M240: 3 | N240: =VLOOKUP(C240,Table1[],7,0) -> EMS | O240: - | P240: - | Q240: - | R240: - | S240: - | T240: - | U240: - | V240: - | W240: - | X240: - | Y240: - | Z240: - | AA240: - | AB240: - | AC240: 0 | AD240: 0 | AE240: 0 | AF240: 0 | AG240: 0 | AH240: 0 | AI240: 44000 | AJ240: برد | AK240: - | AL240: - | AM240: - | AN240: - | AO240: - | AP240: - | AQ240: - | AR240: - | AS240: فرآیندی | AT240: - | AU240: - | AV240: - | AW240: - | AX240: 14000 | AY240: 12000 | AZ240: - | BA240: 14000 | BB240: 12000
A241: 1405/05/28 | C241: 3328510 | D241: سنسور ABS عقب راست 405 و سمند یوفین - دیسکی | E241: =VLOOKUP(C241,Table1[],3,0) -> سنسور ABS عقب راست 405 و سمند یوفین - دیسکی | F241: =VLOOKUP(C241,Table1[],4,0) -> سنسور ABS | G241: =VLOOKUP(C241,Table1[],5,0) -> سنسور ABS عقب راست دیسکی سمند/405 | H241: =VLOOKUP(C241,Table1[],6,0) -> SBS-سیستم های ایمنی ترمز | I241: کنترل نهایی | J241: AD-704 | K241: شکل ظاهری نامناسب تزریق اسکتون | L241: 7 | M241: 4 | N241: =VLOOKUP(C241,Table1[],7,0) -> EMS | O241: - | P241: - | Q241: - | R241: - | S241: - | T241: - | U241: - | V241: - | W241: - | X241: - | Y241: - | Z241: - | AA241: - | AB241: - | AC241: 0 | AD241: 0 | AE241: 0 | AF241: 0 | AG241: 0 | AH241: 0 | AI241: 44000 | AJ241: برد | AK241: - | AL241: - | AM241: - | AN241: - | AO241: - | AP241: - | AQ241: - | AR241: - | AS241: فرآیندی | AT241: - | AU241: - | AV241: - | AW241: - | AX241: 14000 | AY241: 12000 | AZ241: - | BA241: 14000 | BB241: 12000
A242: 1405/06/01 | B242: عادی | C242: 3328509 | D242: سنسور ABS عقب چپ 405 و سمند یوفین - دیسکی | E242: =VLOOKUP(C242,Table1[],3,0) -> سنسور ABS عقب چپ 405 و سمند یوفین - دیسکی | F242: =VLOOKUP(C242,Table1[],4,0) -> سنسور ABS | G242: =VLOOKUP(C242,Table1[],5,0) -> سنسور ABS عقب چپ دیسکی 405 یوفین | H242: =VLOOKUP(C242,Table1[],6,0) -> SBS-سیستم های ایمنی ترمز | I242: کنترل نهایی | J242: AD-704 | K242: شکل ظاهری نامناسب تزریق اسکتون | L242: 2 | M242: 5 | N242: =VLOOKUP(C242,Table1[],7,0) -> EMS | O242: - | P242: - | Q242: - | R242: - | S242: - | T242: - | U242: - | V242: - | W242: - | X242: - | Y242: - | Z242: - | AA242: - | AB242: - | AC242: 0 | AD242: 0 | AE242: 0 | AF242: 0 | AG242: 0 | AH242: 0 | AI242: 44000 | AJ242: برد | AK242: - | AL242: - | AM242: - | AN242: - | AO242: - | AP242: - | AQ242: - | AR242: - | AS242: فرآیندی | AT242: - | AU242: - | AV242: - | AW242: - | AX242: 14000 | AY242: 12000 | AZ242: - | BA242: 14000 | BB242: 12000
A243: 1405/06/02 | B243: عادی | C243: 3328509 | D243: سنسور ABS عقب چپ 405 و سمند یوفین - دیسکی | E243: =VLOOKUP(C243,Table1[],3,0) -> سنسور ABS عقب چپ 405 و سمند یوفین - دیسکی | F243: =VLOOKUP(C243,Table1[],4,0) -> سنسور ABS | G243: =VLOOKUP(C243,Table1[],5,0) -> سنسور ABS عقب چپ دیسکی 405 یوفین | H243: =VLOOKUP(C243,Table1[],6,0) -> SBS-سیستم های ایمنی ترمز | I243: کنترل نهایی | J243: AD-704 | K243: شکل ظاهری نامناسب تزریق اسکتون | L243: 3 | M243: 6 | N243: =VLOOKUP(C243,Table1[],7,0) -> EMS | O243: - | P243: - | Q243: - | R243: - | S243: - | T243: - | U243: - | V243: - | W243: - | X243: - | Y243: - | Z243: - | AA243: - | AB243: - | AC243: 0 | AD243: 0 | AE243: 0 | AF243: 0 | AG243: 0 | AH243: 0 | AI243: 44000 | AJ243: برد | AK243: - | AL243: - | AM243: - | AN243: - | AO243: - | AP243: - | AQ243: - | AR243: - | AS243: فرآیندی | AT243: - | AU243: - | AV243: - | AW243: - | AX243: 14000 | AY243: 12000 | AZ243: - | BA243: 14000 | BB243: 12000
A244: 1405/06/03 | B244: عادی | C244: 3328509 | D244: سنسور ABS عقب چپ 405 و سمند یوفین - دیسکی | E244: =VLOOKUP(C244,Table1[],3,0) -> سنسور ABS عقب چپ 405 و سمند یوفین - دیسکی | F244: =VLOOKUP(C244,Table1[],4,0) -> سنسور ABS | G244: =VLOOKUP(C244,Table1[],5,0) -> سنسور ABS عقب چپ دیسکی 405 یوفین | H244: =VLOOKUP(C244,Table1[],6,0) -> SBS-سیستم های ایمنی ترمز | I244: کنترل نهایی | J244: AD-704 | K244: شکل ظاهری نامناسب تزریق اسکتون | L244: 1 | M244: 7 | N244: =VLOOKUP(C244,Table1[],7,0) -> EMS | O244: - | P244: - | Q244: - | R244: - | S244: - | T244: - | U244: - | V244: - | W244: - | X244: - | Y244: - | Z244: - | AA244: - | AB244: - | AC244: 0 | AD244: 0 | AE244: 0 | AF244: 0 | AG244: 0 | AH244: 0 | AI244: 44000 | AJ244: برد | AK244: - | AL244: - | AM244: - | AN244: - | AO244: - | AP244: - | AQ244: - | AR244: - | AS244: فرآیندی | AT244: - | AU244: - | AV244: - | AW244: - | AX244: 14000 | AY244: 12000 | AZ244: - | BA244: 14000 | BB244: 12000

Sheet ICT
A1: تاریخ | B1: شیفت کاری | C1: کد گروه محصول | D1: کد محصول | E1: نام محصول | F1: خانواده محصول | G1: نام محصول ترکیبی | H1: گروه محصول نهایی | I1: ایستگاه | J1: کد ایراد | K1: شرح ایراد | L1: تعداد ایراد | M1: تعداد کل | N1: برنچ | O1: شرح فعالیت انجام شده توسط تعمیرات | P1: عامل مسبب ایراد 6M | Q1: کد قطعه | R1: نام قطعه | S1: نام تامین کننده | T1: کد و نام تجهیزات و ابزارآلات | U1: کد تجهیزات و ابزارآلات | V1: کد و نام تجهیزات و ابزارآلات1 | W1: کد فرآیند (OPC) | X1: نام فرآیند (OPC) | Y1: حالت خرابی بالقوه | Z1: نوع حالت خرابی بالقوه | AA1: توضیحات تعمیرات | AB1: ستون مشترک حالت خرابی | AC1: شدت حالت خرابی | AD1: تشخیص حالت خرابی | AE1: وقوع قدیمی | AF1: مدت زمان عیب یابی ( دقیقه ) | AG1: مدت زمان رفع عیب ( دقیقه ) | AH1: مدت زمان تست مجدد ( دقیقه ) | AI1: هزینه ریالی تعمیرات | AJ1: خانواده قطعات | AK1: شماره BOM | AL1: شماره برگ ارسال | AM1: کد اپراتور | AN1: نام اپراتور | AO1: کد بازرس چشمی | AP1: نام بازرس | AQ1: AOI | AR1: نام بازرس AOI | AS1: نوع قطعات تولیدی و تامینی | AT1: وضعیت اعلام ایرادات | AU1: توضیحات اضافه | AV1: توضیحات | AW1: Control Station | AX1: حد قابل قبول | AY1: هدف | AZ1: علت افت یا بهبود PPM | BA1: حد قابل قبول عظام | BB1: هدف عظام
A2: 1405/05/01 | B2: - | C2: 1221634 | D2: جعبه الکترونیکی تکمیل کاری شده SBM 206 F1K | E2: =VLOOKUP(C2,Table1[],3,0) -> SBM SOREN | F2: =VLOOKUP(C2,Table1[],4,0) -> SBM | G2: =VLOOKUP(C2,Table1[],5,0) -> SBM | H2: =VLOOKUP(C2,Table1[],6,0) -> Nodes | I2: ICT | J2: ICT_01 | K2: کار نمی کند | L2: 1 | M2: 0 | N2: =VLOOKUP(C2,Table1[],7,0) -> ELE | O2: بازکاری | P2: روش | Q2: 1110401 | R2: IC ULQ2003D1013TRY | S2: - | T2: - | U2: - | V2: - | W2: - | X2: - | Y2: - | Z2: - | AA2: اتصالی | AB2: - | AC2: 0 | AD2: 0 | AE2: 0 | AF2: 5 | AG2: 2 | AH2: 1 | AI2: 44000 | AJ2: IC | AK2: - | AL2: - | AM2: - | AN2: - | AO2: - | AP2: - | AQ2: - | AR2: - | AS2: فرآیندی | AT2: - | AU2: - | AV2: - | AW2: - | AX2: 14000 | AY2: 12000 | AZ2: - | BA2: 14000 | BB2: 12000
A3: 1405/05/01 | B3: - | C3: 1221634 | D3: جعبه الکترونیکی تکمیل کاری شده SBM 206 F1K | E3: =VLOOKUP(C3,Table1[],3,0) -> SBM SOREN | F3: =VLOOKUP(C3,Table1[],4,0) -> SBM | G3: =VLOOKUP(C3,Table1[],5,0) -> SBM | H3: =VLOOKUP(C3,Table1[],6,0) -> Nodes | I3: ICT | J3: ICT_01 | K3: کار نمی کند | L3: 1 | M3: 0 | N3: =VLOOKUP(C3,Table1[],7,0) -> ELE | O3: بازکاری | P3: مواد اولیه | Q3: 1100013 | R3: PCB_SBM_F1K144_C2 | S3: KN | T3: - | U3: - | V3: - | W3: - | X3: - | Y3: - | Z3: - | AA3: چاپ سبز بر روی پد | AB3: - | AC3: 0 | AD3: 0 | AE3: 0 | AF3: 20 | AG3: 6 | AH3: 1 | AI3: 44000 | AJ3: برد | AK3: - | AL3: - | AM3: - | AN3: - | AO3: - | AP3: - | AQ3: - | AR3: - | AS3: فرآیندی | AT3: - | AU3: - | AV3: - | AW3: - | AX3: 14000 | AY3: 12000 | AZ3: - | BA3: 14000 | BB3: 12000
A4: 1405/05/01 | B4: - | C4: 1221634 | D4: جعبه الکترونیکی تکمیل کاری شده SBM 206 F1K | E4: =VLOOKUP(C4,Table1[],3,0) -> SBM SOREN | F4: =VLOOKUP(C4,Table1[],4,0) -> SBM | G4: =VLOOKUP(C4,Table1[],5,0) -> SBM | H4: =VLOOKUP(C4,Table1[],6,0) -> Nodes | I4: ICT | J4: ICT_01 | K4: کار نمی کند | L4: 2 | M4: 0 | N4: =VLOOKUP(C4,Table1[],7,0) -> ELE | O4: تعمیر | P4: روش | Q4: 1110101 | R4: Capacitor 47nF, X7R, 50V, 10% | S4: - | T4: - | U4: - | V4: - | W4: - | X4: - | Y4: - | Z4: - | AA4: قطعه شکسته | AB4: - | AC4: 0 | AD4: 0 | AE4: 0 | AF4: 5 | AG4: 3 | AH4: 1 | AI4: 44000 | AJ4: خازن | AK4: - | AL4: - | AM4: - | AN4: - | AO4: - | AP4: - | AQ4: - | AR4: - | AS4: فرآیندی | AT4: - | AU4: - | AV4: - | AW4: - | AX4: 14000 | AY4: 12000 | AZ4: - | BA4: 14000 | BB4: 12000
A5: 1405/05/01 | B5: - | C5: 1221634 | D5: جعبه الکترونیکی تکمیل کاری شده SBM 206 F1K | E5: =VLOOKUP(C5,Table1[],3,0) -> SBM SOREN | F5: =VLOOKUP(C5,Table1[],4,0) -> SBM | G5: =VLOOKUP(C5,Table1[],5,0) -> SBM | H5: =VLOOKUP(C5,Table1[],6,0) -> Nodes | I5: ICT | J5: ICT_01 | K5: کار نمی کند | L5: 1 | M5: 0 | N5: =VLOOKUP(C5,Table1[],7,0) -> ELE | O5: تعمیر | P5: اپراتور | Q5: 1110901 | R5: Diode 1N4007WS | S5: - | T5: - | U5: - | V5: - | W5: - | X5: - | Y5: - | Z5: - | AA5: جهت قطعه برعکس | AB5: - | AC5: 0 | AD5: 0 | AE5: 0 | AF5: 5 | AG5: 3 | AH5: 1 | AI5: 44000 | AJ5: دیود | AK5: - | AL5: - | AM5: - | AN5: - | AO5: - | AP5: محمد فرضی زاده | AQ5: - | AR5: - | AS5: فرآیندی | AT5: - | AU5: - | AV5: - | AW5: - | AX5: 14000 | AY5: 12000 | AZ5: - | BA5: 14000 | BB5: 12000
A6: 1405/05/01 | B6: - | C6: 1221634 | D6: جعبه الکترونیکی تکمیل کاری شده SBM 206 F1K | E6: =VLOOKUP(C6,Table1[],3,0) -> SBM SOREN | F6: =VLOOKUP(C6,Table1[],4,0) -> SBM | G6: =VLOOKUP(C6,Table1[],5,0) -> SBM | H6: =VLOOKUP(C6,Table1[],6,0) -> Nodes | I6: ICT | J6: ICT_01 | K6: کار نمی کند | L6: 1 | M6: 0 | N6: =VLOOKUP(C6,Table1[],7,0) -> ELE | O6: بازکاری | P6: تجهیرات و ماشین آلات | Q6: 1110075 | R6: Capacitor 10N,50V,X7R,10% | S6: - | T6: - | U6: - | V6: MWS-04/WAVE SOLDERING | W6: - | X6: - | Y6: - | Z6: - | AA6: اتصالی | AB6: - | AC6: 0 | AD6: 0 | AE6: 0 | AF6: 4 | AG6: 5 | AH6: 1 | AI6: 44000 | AJ6: خازن | AK6: - | AL6: - | AM6: - | AN6: - | AO6: - | AP6: - | AQ6: - | AR6: - | AS6: فرآیندی | AT6: - | AU6: - | AV6: - | AW6: - | AX6: 14000 | AY6: 12000 | AZ6: - | BA6: 14000 | BB6: 12000
A7: 1405/05/01 | B7: - | C7: 1221634 | D7: جعبه الکترونیکی تکمیل کاری شده SBM 206 F1K | E7: =VLOOKUP(C7,Table1[],3,0) -> SBM SOREN | F7: =VLOOKUP(C7,Table1[],4,0) -> SBM | G7: =VLOOKUP(C7,Table1[],5,0) -> SBM | H7: =VLOOKUP(C7,Table1[],6,0) -> Nodes | I7: ICT | J7: ICT_01 | K7: کار نمی کند | L7: 1 | M7: 0 | N7: =VLOOKUP(C7,Table1[],7,0) -> ELE | O7: تعمیر | P7: مواد اولیه | Q7: 1110484 | R7: IC BSP78 | S7: - | T7: - | U7: - | V7: - | W7: - | X7: - | Y7: - | Z7: - | AA7: تعویض قطعه | AB7: - | AC7: 0 | AD7: 0 | AE7: 0 | AF7: 9 | AG7: 6 | AH7: 1 | AI7: 44000 | AJ7: IC | AK7: - | AL7: - | AM7: - | AN7: - | AO7: - | AP7: - | AQ7: - | AR7: - | AS7: فرآیندی | AT7: - | AU7: اتصالی | AV7: - | AW7: - | AX7: 14000 | AY7: 12000 | AZ7: - | BA7: 14000 | BB7: 12000
A8: 1405/05/01 | B8: - | C8: 1221634 | D8: جعبه الکترونیکی تکمیل کاری شده SBM 206 F1K | E8: =VLOOKUP(C8,Table1[],3,0) -> SBM SOREN | F8: =VLOOKUP(C8,Table1[],4,0) -> SBM | G8: =VLOOKUP(C8,Table1[],5,0) -> SBM | H8: =VLOOKUP(C8,Table1[],6,0) -> Nodes | I8: ICT | J8: ICT_01 | K8: کار نمی کند | L8: 1 | M8: 0 | N8: =VLOOKUP(C8,Table1[],7,0) -> ELE | O8: تعمیر | P8: روش | Q8: 1110102 | R8: Capacitor 4.7uF,50V,X7R,10% | S8: - | T8: - | U8: - | V8: - | W8: - | X8: - | Y8: - | Z8: - | AA8: قطعه شکسته | AB8: - | AC8: 0 | AD8: 0 | AE8: 0 | AF8: 5 | AG8: 3 | AH8: 1 | AI8: 44000 | AJ8: خازن | AK8: - | AL8: - | AM8: - | AN8: - | AO8: - | AP8: - | AQ8: - | AR8: - | AS8: فرآیندی | AT8: - | AU8: - | AV8: - | AW8: - | AX8: 14000 | AY8: 12000 | AZ8: - | BA8: 14000 | BB8: 12000
A9: 1405/05/01 | B9: - | C9: 1221634 | D9: جعبه الکترونیکی تکمیل کاری شده SBM 206 F1K | E9: =VLOOKUP(C9,Table1[],3,0) -> SBM SOREN | F9: =VLOOKUP(C9,Table1[],4,0) -> SBM | G9: =VLOOKUP(C9,Table1[],5,0) -> SBM | H9: =VLOOKUP(C9,Table1[],6,0) -> Nodes | I9: ICT | J9: ICT_01 | K9: کار نمی کند | L9: 1 | M9: 0 | N9: =VLOOKUP(C9,Table1[],7,0) -> ELE | O9: تعمیر | P9: تجهیرات و ماشین آلات | Q9: 1110901 | R9: Diode 1N4007WS | S9: - | T9: - | U9: - | V9: MLSMD2-06-01/Chip Mounter- SM481 | W9: - | X9: - | Y9: - | Z9: - | AA9: جهت قطعه برعکس | AB9: - | AC9: 0 | AD9: 0 | AE9: 0 | AF9: 5 | AG9: 3 | AH9: 1 | AI9: 44000 | AJ9: دیود | AK9: - | AL9: - | AM9: - | AN9: - | AO9: - | AP9: - | AQ9: - | AR9: - | AS9: فرآیندی | AT9: - | AU9: - | AV9: - | AW9: - | AX9: 14000 | AY9: 12000 | AZ9: - | BA9: 14000 | BB9: 12000
